Workbook

Sheet Trade Log
A1: THE REBOUND — NY + ASIA DAILY TRADE LOG (Jan–Jul 2026)
A2: DATE / DAY | C2: NY SESSION (6:30 AM PT — weekdays only) | K2: ASIA SESSION (3:00 PM PT — incl. Sundays) | S2: DAILY P&L
A3: DATE | B3: DAY | C3: W | D3: L | E3: L✓ | F3: L✗ | G3: S✓ | H3: S✗ | I3: SKIP | J3: E/L | K3: W | L3: L | M3: L✓ | N3: L✗ | O3: S✓ | P3: S✗ | Q3: SKIP | R3: E/L
A4: W=Wins L=Losses L✓=Longs Won L✗=Longs Lost S✓=Shorts Won S✗=Shorts Lost SKIP=# skips E/L = E(early <30min) or L(late >30min) ★ SUNDAY = Asia only
A5: Jan 6 | B5: Tue | S5: =IFERROR(C5*460+D5*-560,0)+IFERROR(K5*460+L5*-560,0) -> 0
A6: Jan 7 | B6: Wed | S6: =IFERROR(C6*460+D6*-560,0)+IFERROR(K6*460+L6*-560,0) -> 0
A7: Jan 8 | B7: Thu | S7: =IFERROR(C7*460+D7*-560,0)+IFERROR(K7*460+L7*-560,0) -> 0
A8: Jan 9 | B8: Fri | S8: =IFERROR(C8*460+D8*-560,0)+IFERROR(K8*460+L8*-560,0) -> 0
A9: Jan 11 | B9: SUN ★ | C9: — | D9: — | E9: — | F9: — | G9: — | H9: — | I9: — | J9: — | K9: 1 | L9: 1 | N9: 1 | O9: 1 | Q9: 1 | R9: L | S9: =IFERROR(K9*460+L9*-560,0) -> -100
A10: Jan 12 | B10: Mon | C10: 1 | E10: 1 | J10: L | K10: 1 | N10: 1 | R10: L | S10: =IFERROR(C10*460+D10*-560,0)+IFERROR(K10*460+L10*-560,0) -> 920
A11: Jan 13 | B11: Tue | C11: 1 | D11: 1 | G11: 1 | H11: 1 | J11: L | K11: 2 | M11: 1 | O11: 1 | Q11: 1 | R11: L | S11: =IFERROR(C11*460+D11*-560,0)+IFERROR(K11*460+L11*-560,0) -> 820
A12: Jan 14 | B12: Wed | C12: 1 | D12: 3 | E12: 1 | F12: 1 | H12: 2 | J12: L | K12: 2 | L12: 2 | M12: 1 | N12: 1 | O12: 1 | P12: 1 | R12: E/L | S12: =IFERROR(C12*460+D12*-560,0)+IFERROR(K12*460+L12*-560,0) -> -1420
A13: Jan 15 | B13: Thu | C13: 2 | D13: 1 | E13: 1 | G13: 1 | H13: 1 | J13: E/L | K13: 2 | M13: 2 | R13: E/L | S13: =IFERROR(C13*460+D13*-560,0)+IFERROR(K13*460+L13*-560,0) -> 1280
A14: Jan 16 | B14: Fri | C14: 3 | D14: 1 | E14: 1 | F14: 1 | G14: 2 | I14: 1 | J14: E/L | K14: 1 | O14: 1 | Q14: 1 | R14: L | S14: =IFERROR(C14*460+D14*-560,0)+IFERROR(K14*460+L14*-560,0) -> 1280
A15: Jan 18 | B15: SUN ★ | C15: — | D15: — | E15: — | F15: — | G15: — | H15: — | I15: — | J15: — | K15: 1 | O15: 1 | Q15: 1 | R15: L | S15: =IFERROR(K15*460+L15*-560,0) -> 460
A16: Jan 20 | B16: Tue | C16: 1 | D16: 2 | E16: 1 | H16: 2 | I16: 3 | J16: L | L16: 2 | P16: 2 | R16: L | S16: =IFERROR(C16*460+D16*-560,0)+IFERROR(K16*460+L16*-560,0) -> -1780
A17: Jan 21 | B17: Wed | D17: 2 | F17: 2 | H17: 2 | J17: L | L17: 1 | N17: 1 | R17: E | S17: =IFERROR(C17*460+D17*-560,0)+IFERROR(K17*460+L17*-560,0) -> -1680
A18: Jan 22 | B18: Thu | C18: 1 | D18: 3 | E18: 1 | F18: 1 | H18: 2 | J18: L | K18: 2 | L18: 1 | M18: 2 | P18: 1 | R18: E/L | S18: =IFERROR(C18*460+D18*-560,0)+IFERROR(K18*460+L18*-560,0) -> -860
A19: Jan 23 | B19: Fri | C19: 2 | E19: 1 | G19: 1 | I19: 1 | J19: L | S19: =IFERROR(C19*460+D19*-560,0)+IFERROR(K19*460+L19*-560,0) -> 920
A20: Jan 25 | B20: SUN ★ | C20: — | D20: — | E20: — | F20: — | G20: — | H20: — | I20: — | J20: — | K20: 1 | L20: 2 | M20: 1 | N20: 1 | O20: 1 | R20: E/L | S20: =IFERROR(K20*460+L20*-560,0) -> -660
A21: Jan 26 | B21: Mon | D21: 2 | F21: 2 | J21: L | K21: 1 | M21: 1 | R21: L | S21: =IFERROR(C21*460+D21*-560,0)+IFERROR(K21*460+L21*-560,0) -> -660
A22: Jan 27 | B22: Tue | C22: 4 | D22: 1 | E22: 3 | F22: 1 | J22: L | K22: 1 | M22: 1 | R22: E | S22: =IFERROR(C22*460+D22*-560,0)+IFERROR(K22*460+L22*-560,0) -> 1740
A23: Jan 28 | B23: Wed | C23: 2 | D23: 1 | E23: 2 | F23: 1 | I23: 1 | J23: E/L | K23: 2 | M23: 1 | O23: 1 | R23: L | S23: =IFERROR(C23*460+D23*-560,0)+IFERROR(K23*460+L23*-560,0) -> 1280
A24: Jan 29 | B24: Thu | C24: 3 | D24: 1 | E24: 2 | F24: 1 | G24: 1 | I24: 4 | J24: E/L | K24: 3 | L24: 1 | M24: 1 | N24: 1 | O24: 2 | Q24: 1 | R24: L | S24: =IFERROR(C24*460+D24*-560,0)+IFERROR(K24*460+L24*-560,0) -> 1640
A25: Jan 30 | B25: Fri | C25: 1 | G25: 1 | J25: E | S25: =IFERROR(C25*460+D25*-560,0)+IFERROR(K25*460+L25*-560,0) -> 460
A26: ★ JANUARY TOTAL | C26: =SUM(C5:C25) -> 22 | D26: =SUM(D5:D25) -> 18 | E26: =SUM(E5:E25) -> 14 | F26: =SUM(F5:F25) -> 10 | G26: =SUM(G5:G25) -> 7 | H26: =SUM(H5:H25) -> 10 | I26: =SUM(I5:I25) -> 10 | K26: =SUM(K5:K25) -> 20 | L26: =SUM(L5:L25) -> 10 | M26: =SUM(M5:M25) -> 11 | N26: =SUM(N5:N25) -> 6 | O26: =SUM(O5:O25) -> 9 | P26: =SUM(P5:P25) -> 4 | Q26: =SUM(Q5:Q25) -> 5 | S26: =SUM(S5:S25) -> 3640
A27: Feb 1 | B27: SUN ★ | C27: — | D27: — | E27: — | F27: — | G27: — | H27: — | I27: — | J27: — | L27: 2 | N27: 1 | P27: 1 | Q27: 1 | R27: L | S27: =IFERROR(K27*460+L27*-560,0) -> -1120
A28: Feb 2 | B28: Mon | C28: 1 | D28: 2 | E28: 1 | F28: 1 | H28: 1 | J28: E/L | K28: 1 | L28: 1 | O28: 1 | Q28: 1 | R28: L | S28: =IFERROR(C28*460+D28*-560,0)+IFERROR(K28*460+L28*-560,0) -> -760
A29: Feb 3 | B29: Tue | C29: 1 | D29: 2 | G29: 1 | H29: 2 | J29: L | K29: 1 | L29: 1 | N29: 1 | O29: 1 | R29: L | S29: =IFERROR(C29*460+D29*-560,0)+IFERROR(K29*460+L29*-560,0) -> -760
A30: Feb 4 | B30: Wed | K30: 1 | L30: 1 | N30: 1 | O30: 1 | R30: L | S30: =IFERROR(C30*460+D30*-560,0)+IFERROR(K30*460+L30*-560,0) -> -100
A31: Feb 5 | B31: Thu | D31: 1 | F31: 1 | I31: 2 | J31: L | K31: 1 | L31: 2 | M31: 1 | N31: 2 | R31: L | S31: =IFERROR(C31*460+D31*-560,0)+IFERROR(K31*460+L31*-560,0) -> -1220
A32: Feb 6 | B32: Fri | C32: 2 | D32: 2 | E32: 2 | F32: 1 | H32: 1 | J32: E/L | S32: =IFERROR(C32*460+D32*-560,0)+IFERROR(K32*460+L32*-560,0) -> -200
A33: Feb 8 | B33: SUN ★ | C33: — | D33: — | E33: — | F33: — | G33: — | H33: — | I33: — | J33: — | K33: 1 | L33: 2 | M33: 1 | N33: 2 | Q33: 2 | R33: L | S33: =IFERROR(K33*460+L33*-560,0) -> -660
A34: Feb 9 | B34: Mon | C34: 1 | D34: 2 | E34: 1 | F34: 2 | J34: L | K34: 1 | L34: 2 | N34: 2 | O34: 1 | R34: L | S34: =IFERROR(C34*460+D34*-560,0)+IFERROR(K34*460+L34*-560,0) -> -1320
A35: Feb 10 | B35: Tue | C35: 1 | E35: 1 | I35: 1 | J35: L | K35: 1 | L35: 1 | M35: 1 | N35: 1 | R35: L | S35: =IFERROR(C35*460+D35*-560,0)+IFERROR(K35*460+L35*-560,0) -> 360
A36: Feb 11 | B36: Wed | C36: 2 | D36: 1 | E36: 2 | F36: 1 | J36: L | L36: 1 | Q36: 1 | R36: L | S36: =IFERROR(C36*460+D36*-560,0)+IFERROR(K36*460+L36*-560,0) -> -200
A37: Feb 12 | B37: Thu | C37: 2 | E37: 1 | G37: 1 | I37: 7 | J37: E/L | K37: 2 | Q37: 1 | R37: L | S37: =IFERROR(C37*460+D37*-560,0)+IFERROR(K37*460+L37*-560,0) -> 1840
A38: Feb 13 | B38: Fri | S38: =IFERROR(C38*460+D38*-560,0)+IFERROR(K38*460+L38*-560,0) -> 0
A39: Feb 15 | B39: SUN ★ | C39: — | D39: — | E39: — | F39: — | G39: — | H39: — | I39: — | J39: — | S39: =IFERROR(K39*460+L39*-560,0) -> 0
A40: Feb 17 | B40: Tue | C40: 3 | D40: 1 | E40: 2 | G40: 1 | H40: 1 | I40: 2 | J40: E/L | L40: 2 | P40: 2 | R40: L | S40: =IFERROR(C40*460+D40*-560,0)+IFERROR(K40*460+L40*-560,0) -> -300
...

Sheet Stats
A1: BACKTEST STATS — NY + ASIA COMBINED
A2: METRIC | B2: NY | C2: ASIA | D2: COMBINED
A3: OVERALL
A4: Total Trades | B4: =SUM('Trade Log'!C5:C159)+SUM('Trade Log'!D5:D159) -> 228 | C4: =SUM('Trade Log'!K5:K159)+SUM('Trade Log'!L5:L159) -> 190 | D4: =B4+C4 -> 418
A5: Wins | B5: =SUM('Trade Log'!C5:C159) -> 112 | C5: =SUM('Trade Log'!K5:K159) -> 102 | D5: =B5+C5 -> 214
A6: Losses | B6: =SUM('Trade Log'!D5:D159) -> 116 | C6: =SUM('Trade Log'!L5:L159) -> 88 | D6: =B6+C6 -> 204
A7: Win Rate | B7: =IFERROR(B5/B4,0) -> 0.49122807 | C7: =IFERROR(C5/C4,0) -> 0.53684211 | D7: =IFERROR(D5/D4,0) -> 0.51196172
A8: Net P&L | B8: =SUM('Trade Log'!C5:C159)*460+SUM('Trade Log'!D5:D159)*-560 -> -13440 | C8: =SUM('Trade Log'!K5:K159)*460+SUM('Trade Log'!L5:L159)*-560 -> -2360 | D8: =SUM('Trade Log'!S5:S159) -> -15800
A9: Profit Factor | B9: =IFERROR((B5*460)/(B6*560),0) -> 0.79310345 | C9: =IFERROR((C5*460)/(C6*560),0) -> 0.95211039 | D9: =IFERROR((D5*460)/(D6*560),0) -> 0.86169468
A10: Expectancy/Trade | B10: =IFERROR(B8/B4,0) -> -58.947368 | C10: =IFERROR(C8/C4,0) -> -12.421053 | D10: =IFERROR(D8/D4,0) -> -37.799043
A11: LONGS
A12: Longs Won | B12: =SUM('Trade Log'!E5:E159) -> 66 | C12: =SUM('Trade Log'!M5:M159) -> 48 | D12: =B12+C12 -> 114
A13: Longs Lost | B13: =SUM('Trade Log'!F5:F159) -> 54 | C13: =SUM('Trade Log'!N5:N159) -> 54 | D13: =B13+C13 -> 108
A14: Long Win Rate | B14: =IFERROR(B12/(B12+B13),0) -> 0.55 | C14: =IFERROR(C12/(C12+C13),0) -> 0.47058824 | D14: =IFERROR(D12/(D12+D13),0) -> 0.51351351
A15: SHORTS
A16: Shorts Won | B16: =SUM('Trade Log'!G5:G159) -> 44 | C16: =SUM('Trade Log'!O5:O159) -> 48 | D16: =B16+C16 -> 92
A17: Shorts Lost | B17: =SUM('Trade Log'!H5:H159) -> 58 | C17: =SUM('Trade Log'!P5:P159) -> 26 | D17: =B17+C17 -> 84
A18: Short Win Rate | B18: =IFERROR(B16/(B16+B17),0) -> 0.43137255 | C18: =IFERROR(C16/(C16+C17),0) -> 0.64864865 | D18: =IFERROR(D16/(D16+D17),0) -> 0.52272727
A19: SKIPS
A20: Total Skips | B20: =SUM('Trade Log'!I5:I159) -> 84 | C20: =SUM('Trade Log'!Q5:Q159) -> 54 | D20: =B20+C20 -> 138
